Workbook

Sheet Sheet1
A1: SN | B1: Electricity Number | C1: From | D1: To | E1: Asset Tag | F1: Field Tag | G1: GPS | H1: Area | I1: Zone | J1: Street | K1: Coordinates
A2: 1 | B2: 1252411 | C2: 46070.312 | D2: 46070.521 | E2: {=IF(B2="","",XLOOKUP($B2,Sheet2!$I:$I,Sheet2!$T:$T,""))} | F2: {=IF($B2="","",XLOOKUP($B2,Sheet2!$I:$I,Sheet2!$E:$E,""))} | G2: {=IF($B2="","",XLOOKUP($B2,Sheet2!$I:$I,Sheet2!$C:$C,""))} | H2: West Bay (Al Doha Al Hadetha) | I2: 69 | J2: 100 | K2: 25.390900, 51.518883
A3: 2 | B3: 906994 | C3: 46075.312 | D3: 46075.604 | E3: {=IF(B3="","",XLOOKUP($B3,Sheet2!$I:$I,Sheet2!$T:$T,""))} | F3: {=IF($B3="","",XLOOKUP($B3,Sheet2!$I:$I,Sheet2!$E:$E,""))} | G3: {=IF($B3="","",XLOOKUP($B3,Sheet2!$I:$I,Sheet2!$C:$C,""))} | H3: Al Gharrafa / Bani Hajer | I3: 51 | J3: 720 | K3: 25.330952, 51.463870
A4: 3 | B4: 1413363 | C4: 46075.312 | D4: 46075.604 | E4: {=IF(B4="","",XLOOKUP($B4,Sheet2!$I:$I,Sheet2!$T:$T,""))} | F4: {=IF($B4="","",XLOOKUP($B4,Sheet2!$I:$I,Sheet2!$E:$E,""))} | G4: {=IF($B4="","",XLOOKUP($B4,Sheet2!$I:$I,Sheet2!$C:$C,""))} | H4: Al Gharrafa / Bani Hajer | I4: 51 | J4: 720 | K4: 25.331254, 51.463825
A5: 4 | B5: 1407987 | C5: 46076.312 | D5: 46076.604 | E5: {=IF(B5="","",XLOOKUP($B5,Sheet2!$I:$I,Sheet2!$T:$T,""))} | F5: {=IF($B5="","",XLOOKUP($B5,Sheet2!$I:$I,Sheet2!$E:$E,""))} | G5: {=IF($B5="","",XLOOKUP($B5,Sheet2!$I:$I,Sheet2!$C:$C,""))} | H5: Industrial Area | I5: 57 | J5: 38 | K5: 25.182765, 51.449207
A6: 5 | B6: 907085 | C6: 46076.312 | D6: 46076.604 | E6: {=IF(B6="","",XLOOKUP($B6,Sheet2!$I:$I,Sheet2!$T:$T,""))} | F6: {=IF($B6="","",XLOOKUP($B6,Sheet2!$I:$I,Sheet2!$E:$E,""))} | G6: {=IF($B6="","",XLOOKUP($B6,Sheet2!$I:$I,Sheet2!$C:$C,""))} | H6: Al-Kheesa | I6: 70 | J6: 970 | K6: 25.382497, 51.477593
A7: 6 | B7: 1284934 | C7: 46079.375 | D7: 46079.458 | E7: {=IF(B7="","",XLOOKUP($B7,Sheet2!$I:$I,Sheet2!$T:$T,""))} | F7: {=IF($B7="","",XLOOKUP($B7,Sheet2!$I:$I,Sheet2!$E:$E,""))} | G7: {=IF($B7="","",XLOOKUP($B7,Sheet2!$I:$I,Sheet2!$C:$C,""))} | H7: Al-Kheesa | I7: 70 | J7: 879 | K7: 25.643664, 51.484475,25.645532, 51.478757,25.643653, 51.487906,25.646349, 51.479198,25.645017, 51.481277,25.645489, 51.481880,25.640784, 51.486730,25.637950, 51.488171,25.647570, 51.476258 | L7: ,
A8: 7 | B8: 1364567 | C8: 46097.333 | D8: 46097.417 | E8: {=IF(B8="","",XLOOKUP($B8,Sheet2!$I:$I,Sheet2!$T:$T,""))} | F8: {=IF($B8="","",XLOOKUP($B8,Sheet2!$I:$I,Sheet2!$E:$E,""))} | G8: {=IF($B8="","",XLOOKUP($B8,Sheet2!$I:$I,Sheet2!$C:$C,""))} | H8: Al Gharrafa / Bani Hajer | I8: 51 | J8: 1298 | K8: 25.351703, 51.395831
A9: 8 | B9: 1356764 | C9: 46095.406 | D9: 46095.427 | E9: {=IF(B9="","",XLOOKUP($B9,Sheet2!$I:$I,Sheet2!$T:$T,""))} | F9: {=IF($B9="","",XLOOKUP($B9,Sheet2!$I:$I,Sheet2!$E:$E,""))} | G9: {=IF($B9="","",XLOOKUP($B9,Sheet2!$I:$I,Sheet2!$C:$C,""))} | H9: Madinat Khalifa (south) | I9: 32 | J9: 370 | K9: 25.322016, 51.474363
A10: 9 | B10: 1088219 | C10: 46107.271 | D10: 46107.604 | E10: {=IF(B10="","",XLOOKUP($B10,Sheet2!$I:$I,Sheet2!$T:$T,""))} | F10: {=IF($B10="","",XLOOKUP($B10,Sheet2!$I:$I,Sheet2!$E:$E,""))} | G10: {=IF($B10="","",XLOOKUP($B10,Sheet2!$I:$I,Sheet2!$C:$C,""))} | H10: West Bay (Al-Doha Al-Hadetha) | I10: 66 | J10: 18 | K10: 25.361743, 51.509908
A11: 10 | B11: 1387118 | C11: 46107.292 | D11: 46107.458 | E11: {=IF(B11="","",XLOOKUP($B11,Sheet2!$I:$I,Sheet2!$T:$T,""))} | F11: {=IF($B11="","",XLOOKUP($B11,Sheet2!$I:$I,Sheet2!$E:$E,""))} | G11: {=IF($B11="","",XLOOKUP($B11,Sheet2!$I:$I,Sheet2!$C:$C,""))} | H11: Umm slal / Khreteat | I11: 71 | J11: 39 | K11: 25.366980, 51.430446
A12: 11 | B12: 1353295 | C12: 46107.271 | D12: 46107.583 | E12: {=IF(B12="","",XLOOKUP($B12,Sheet2!$I:$I,Sheet2!$T:$T,""))} | F12: {=IF($B12="","",XLOOKUP($B12,Sheet2!$I:$I,Sheet2!$E:$E,""))} | G12: {=IF($B12="","",XLOOKUP($B12,Sheet2!$I:$I,Sheet2!$C:$C,""))} | H12: Al Soudan-S/Al Aziziya/Al Ghan | I12: 55 | J12: 509 | K12: 25.249431, 51.447574
A13: 12 | B13: 1009761 | C13: 46107.271 | D13: 46107.583 | E13: {=IF(B13="","",XLOOKUP($B13,Sheet2!$I:$I,Sheet2!$T:$T,""))} | F13: {=IF($B13="","",XLOOKUP($B13,Sheet2!$I:$I,Sheet2!$E:$E,""))} | G13: {=IF($B13="","",XLOOKUP($B13,Sheet2!$I:$I,Sheet2!$C:$C,""))} | H13: Industrial Area | I13: 57 | J13: 1 | K13: 25.211705, 51.419186
A14: 13 | B14: 1393575 | C14: 46107.292 | D14: 46107.458 | E14: {=IF(B14="","",XLOOKUP($B14,Sheet2!$I:$I,Sheet2!$T:$T,""))} | F14: {=IF($B14="","",XLOOKUP($B14,Sheet2!$I:$I,Sheet2!$E:$E,""))} | G14: {=IF($B14="","",XLOOKUP($B14,Sheet2!$I:$I,Sheet2!$C:$C,""))} | H14: Al-Wkeer | I14: 91 | J14: 212 | K14: 25.184965, 51.568818
A15: 14 | B15: 1391140 | C15: 46107.292 | D15: 46107.458 | E15: {=IF(B15="","",XLOOKUP($B15,Sheet2!$I:$I,Sheet2!$T:$T,""))} | F15: {=IF($B15="","",XLOOKUP($B15,Sheet2!$I:$I,Sheet2!$E:$E,""))} | G15: {=IF($B15="","",XLOOKUP($B15,Sheet2!$I:$I,Sheet2!$C:$C,""))} | H15: Al-Wkeer | I15: 91 | J15: 212 | K15: 25.185044, 51.568823
A16: 15 | B16: 1395103 | C16: 46107.271 | D16: 46107.583 | E16: {=IF(B16="","",XLOOKUP($B16,Sheet2!$I:$I,Sheet2!$T:$T,""))} | F16: {=IF($B16="","",XLOOKUP($B16,Sheet2!$I:$I,Sheet2!$E:$E,""))} | G16: {=IF($B16="","",XLOOKUP($B16,Sheet2!$I:$I,Sheet2!$C:$C,""))} | H16: Al-Kheesa | I16: 70 | J16: 590 | K16: 25.414359, 51.440747
A17: 16 | B17: 1365673 | C17: 46105.539 | D17: 46105.539 | E17: {=IF(B17="","",XLOOKUP($B17,Sheet2!$I:$I,Sheet2!$T:$T,""))} | F17: {=IF($B17="","",XLOOKUP($B17,Sheet2!$I:$I,Sheet2!$E:$E,""))} | H17: Al-Mergab - Al-Naser | I17: 39 | J17: 231 | K17: 25.275834, 51.508278
A18: 17 | B18: 1273538 | C18: 46106.292 | D18: 46106.5 | E18: {=IF(B18="","",XLOOKUP($B18,Sheet2!$I:$I,Sheet2!$T:$T,""))} | F18: {=IF($B18="","",XLOOKUP($B18,Sheet2!$I:$I,Sheet2!$E:$E,""))} | G18: {=IF($B18="","",XLOOKUP($B18,Sheet2!$I:$I,Sheet2!$C:$C,""))} | H18: Al-Wkeer | I18: 91 | J18: 100 | K18: 25.180244, 51.581228
A19: 18 | B19: 1353727 | C19: 46106.292 | D19: 46106.583 | E19: {=IF(B19="","",XLOOKUP($B19,Sheet2!$I:$I,Sheet2!$T:$T,""))} | F19: {=IF($B19="","",XLOOKUP($B19,Sheet2!$I:$I,Sheet2!$E:$E,""))} | G19: {=IF($B19="","",XLOOKUP($B19,Sheet2!$I:$I,Sheet2!$C:$C,""))} | H19: Al Roodah | I19: 46 | J19: 800 | K19: 25.236635, 51.548794
A20: 19 | B20: 1390152 | C20: 46106.417 | D20: 46106.583 | E20: {=IF(B20="","",XLOOKUP($B20,Sheet2!$I:$I,Sheet2!$T:$T,""))} | F20: {=IF($B20="","",XLOOKUP($B20,Sheet2!$I:$I,Sheet2!$E:$E,""))} | G20: {=IF($B20="","",XLOOKUP($B20,Sheet2!$I:$I,Sheet2!$C:$C,""))} | H20: Al Gharrafa / Bani Hajer | I20: 51 | J20: 191 | K20: 25.364557, 51.426855
A21: 20 | B21: 1354115 | C21: 46106.417 | D21: 46106.583 | E21: {=IF(B21="","",XLOOKUP($B21,Sheet2!$I:$I,Sheet2!$T:$T,""))} | F21: {=IF($B21="","",XLOOKUP($B21,Sheet2!$I:$I,Sheet2!$E:$E,""))} | G21: {=IF($B21="","",XLOOKUP($B21,Sheet2!$I:$I,Sheet2!$C:$C,""))} | H21: Al-Gwerea | I21: 76 | J21: 818 | K21: 25.827171, 51.246183
A22: 21 | B22: 1453309 | C22: 46106.292 | D22: 46106.458 | E22: {=IF(B22="","",XLOOKUP($B22,Sheet2!$I:$I,Sheet2!$T:$T,""))} | F22: {=IF($B22="","",XLOOKUP($B22,Sheet2!$I:$I,Sheet2!$E:$E,""))} | G22: {=IF($B22="","",XLOOKUP($B22,Sheet2!$I:$I,Sheet2!$C:$C,""))} | H22: Al-Wkeer | I22: 91 | J22: 212 | K22: 25.176247, 51.568940
A23: 22 | B23: 1413765 | C23: 46106.292 | D23: 46106.458 | E23: {=IF(B23="","",XLOOKUP($B23,Sheet2!$I:$I,Sheet2!$T:$T,""))} | F23: {=IF($B23="","",XLOOKUP($B23,Sheet2!$I:$I,Sheet2!$E:$E,""))} | G23: {=IF($B23="","",XLOOKUP($B23,Sheet2!$I:$I,Sheet2!$C:$C,""))} | H23: Al-Wkeer | I23: 91 | J23: 212 | K23: 25.171078, 51.569446
A24: 23 | B24: 1453310 | C24: 46106.292 | D24: 46106.458 | E24: {=IF(B24="","",XLOOKUP($B24,Sheet2!$I:$I,Sheet2!$T:$T,""))} | F24: {=IF($B24="","",XLOOKUP($B24,Sheet2!$I:$I,Sheet2!$E:$E,""))} | G24: {=IF($B24="","",XLOOKUP($B24,Sheet2!$I:$I,Sheet2!$C:$C,""))} | H24: Al-Wkeer | I24: 91 | J24: 212 | K24: 25.174059, 51.569044
A25: 24 | B25: 1413846 | C25: 46106.292 | D25: 46106.458 | E25: {=IF(B25="","",XLOOKUP($B25,Sheet2!$I:$I,Sheet2!$T:$T,""))} | F25: {=IF($B25="","",XLOOKUP($B25,Sheet2!$I:$I,Sheet2!$E:$E,""))} | G25: {=IF($B25="","",XLOOKUP($B25,Sheet2!$I:$I,Sheet2!$C:$C,""))} | H25: West Bay (Al-Doha Al-Hadetha) | I25: 91 | J25: 212 | K25: 25.173571, 51.568709
A26: 25 | B26: 1393425 | C26: 46106.271 | D26: 46106.583 | E26: {=IF(B26="","",XLOOKUP($B26,Sheet2!$I:$I,Sheet2!$T:$T,""))} | F26: {=IF($B26="","",XLOOKUP($B26,Sheet2!$I:$I,Sheet2!$E:$E,""))} | G26: {=IF($B26="","",XLOOKUP($B26,Sheet2!$I:$I,Sheet2!$C:$C,""))} | H26: Al Soudan-S/Al Aziziya/Al Ghan | I26: 55 | J26: 971 | K26: 25.263084, 51.409587
A27: 26 | B27: 1391201 | C27: 46110.312 | D27: 46110.604 | E27: {=IF(B27="","",XLOOKUP($B27,Sheet2!$I:$I,Sheet2!$T:$T,""))} | F27: {=IF($B27="","",XLOOKUP($B27,Sheet2!$I:$I,Sheet2!$E:$E,""))} | G27: {=IF($B27="","",XLOOKUP($B27,Sheet2!$I:$I,Sheet2!$C:$C,""))} | H27: Industrial Area | I27: 57 | J27: 115 | K27: 25.179022, 51.451877
A28: 27 | B28: 1391271 | C28: 46110.292 | D28: 46110.583 | E28: {=IF(B28="","",XLOOKUP($B28,Sheet2!$I:$I,Sheet2!$T:$T,""))} | F28: {=IF($B28="","",XLOOKUP($B28,Sheet2!$I:$I,Sheet2!$E:$E,""))} | G28: {=IF($B28="","",XLOOKUP($B28,Sheet2!$I:$I,Sheet2!$C:$C,""))} | H28: Industrial Area | I28: 57 | J28: 10 | K28: 25.210534, 51.434587
A29: 28 | B29: 1270820 | C29: 46110.271 | D29: 46110.583 | E29: {=IF(B29="","",XLOOKUP($B29,Sheet2!$I:$I,Sheet2!$T:$T,""))} | F29: {=IF($B29="","",XLOOKUP($B29,Sheet2!$I:$I,Sheet2!$E:$E,""))} | G29: {=IF($B29="","",XLOOKUP($B29,Sheet2!$I:$I,Sheet2!$C:$C,""))} | H29: Al-Thekhera | I29: 75 | J29: 82 | K29: 25.784933, 51.566897
A30: 29 | B30: 1394996 | C30: 46107.458 | D30: 46107.583 | E30: {=IF(B30="","",XLOOKUP($B30,Sheet2!$I:$I,Sheet2!$T:$T,""))} | F30: {=IF($B30="","",XLOOKUP($B30,Sheet2!$I:$I,Sheet2!$E:$E,""))} | G30: {=IF($B30="","",XLOOKUP($B30,Sheet2!$I:$I,Sheet2!$C:$C,""))} | H30: Al-Mamoura - Ain Khaled - Al-K | I30: 56 | J30: 604 | K30: 25.229228, 51.481781
A31: 30 | B31: 1398618 | C31: 46110.271 | D31: 46110.583 | E31: {=IF(B31="","",XLOOKUP($B31,Sheet2!$I:$I,Sheet2!$T:$T,""))} | F31: {=IF($B31="","",XLOOKUP($B31,Sheet2!$I:$I,Sheet2!$E:$E,""))} | G31: {=IF($B31="","",XLOOKUP($B31,Sheet2!$I:$I,Sheet2!$C:$C,""))} | H31: Fwert - Al-jasasea | I31: 77 | K31: 25.992448, 51.396887
A32: 31 | B32: 1395103 | C32: 46107.271 | D32: 46107.583 | E32: {=IF(B32="","",XLOOKUP($B32,Sheet2!$I:$I,Sheet2!$T:$T,""))} | F32: {=IF($B32="","",XLOOKUP($B32,Sheet2!$I:$I,Sheet2!$E:$E,""))} | G32: {=IF($B32="","",XLOOKUP($B32,Sheet2!$I:$I,Sheet2!$C:$C,""))} | H32: Abu -Nakla/ Mkeens | I32: 70 | J32: 590 | K32: 25.414359, 51.440747 | L32: Cancelled
A33: 32 | B33: 1353295 | C33: 46107.271 | D33: 46107.583 | E33: {=IF(B33="","",XLOOKUP($B33,Sheet2!$I:$I,Sheet2!$T:$T,""))} | F33: {=IF($B33="","",XLOOKUP($B33,Sheet2!$I:$I,Sheet2!$E:$E,""))} | G33: {=IF($B33="","",XLOOKUP($B33,Sheet2!$I:$I,Sheet2!$C:$C,""))} | H33: Abu -Nakla/ Mkeens | I33: 55 | J33: 509 | K33: 25.249431, 51.447574 | L33: Cancelled
A34: 33 | B34: 1009761 | C34: 46107.271 | D34: 46107.583 | E34: {=IF(B34="","",XLOOKUP($B34,Sheet2!$I:$I,Sheet2!$T:$T,""))} | F34: {=IF($B34="","",XLOOKUP($B34,Sheet2!$I:$I,Sheet2!$E:$E,""))} | G34: {=IF($B34="","",XLOOKUP($B34,Sheet2!$I:$I,Sheet2!$C:$C,""))} | H34: Abu -Nakla/ Mkeens | I34: 57 | J34: 1 | K34: 25.211705, 51.419186 | L34: cancelled
A35: 34 | B35: 1373070 | C35: 46111.271 | D35: 46111.583 | E35: {=IF(B35="","",XLOOKUP($B35,Sheet2!$I:$I,Sheet2!$T:$T,""))} | F35: {=IF($B35="","",XLOOKUP($B35,Sheet2!$I:$I,Sheet2!$E:$E,""))} | G35: {=IF($B35="","",XLOOKUP($B35,Sheet2!$I:$I,Sheet2!$C:$C,""))} | H35: Al-Krara | I35: 95 | J35: 204 | K35: 24.901916, 51.176422
A36: 35 | B36: 1353378 | C36: 46111.292 | D36: 46111.583 | E36: {=IF(B36="","",XLOOKUP($B36,Sheet2!$I:$I,Sheet2!$T:$T,""))} | F36: {=IF($B36="","",XLOOKUP($B36,Sheet2!$I:$I,Sheet2!$E:$E,""))} | G36: {=IF($B36="","",XLOOKUP($B36,Sheet2!$I:$I,Sheet2!$C:$C,""))} | H36: Abu -Nakla/ Mkeens | I36: 81 | J36: 324 | K36: 25.183665, 51.376020
A37: 36 | B37: 1373781 | C37: 46112.417 | D37: 46112.604 | E37: {=IF(B37="","",XLOOKUP($B37,Sheet2!$I:$I,Sheet2!$T:$T,""))} | F37: {=IF($B37="","",XLOOKUP($B37,Sheet2!$I:$I,Sheet2!$E:$E,""))} | G37: {=IF($B37="","",XLOOKUP($B37,Sheet2!$I:$I,Sheet2!$C:$C,""))} | H37: Al-Khoor | I37: 74 | J37: 571 | K37: 25.664927, 51.497221
A38: 37 | B38: 1365905 | C38: 46112.312 | D38: 46112.604 | E38: {=IF(B38="","",XLOOKUP($B38,Sheet2!$I:$I,Sheet2!$T:$T,""))} | F38: {=IF($B38="","",XLOOKUP($B38,Sheet2!$I:$I,Sheet2!$E:$E,""))} | G38: {=IF($B38="","",XLOOKUP($B38,Sheet2!$I:$I,Sheet2!$C:$C,""))} | H38: Umm slal / Khreteat | I38: 71 | J38: 270 | K38: 25.542574, 51.408294
A39: 38 | B39: 1131539 | C39: 46113.417 | D39: 46113.604 | E39: {=IF(B39="","",XLOOKUP($B39,Sheet2!$I:$I,Sheet2!$T:$T,""))} | F39: {=IF($B39="","",XLOOKUP($B39,Sheet2!$I:$I,Sheet2!$E:$E,""))} | G39: {=IF($B39="","",XLOOKUP($B39,Sheet2!$I:$I,Sheet2!$C:$C,""))} | H39: Umm slal / Khreteat | I39: 51 | J39: 1755 | K39: 25.340824, 51.364530
A40: 39 | B40: 1353611 | C40: 46113.417 | D40: 46113.604 | E40: {=IF(B40="","",XLOOKUP($B40,Sheet2!$I:$I,Sheet2!$T:$T,""))} | F40: {=IF($B40="","",XLOOKUP($B40,Sheet2!$I:$I,Sheet2!$E:$E,""))} | G40: {=IF($B40="","",XLOOKUP($B40,Sheet2!$I:$I,Sheet2!$C:$C,""))} | H40: Al Gharrafa / Bani Hajer | I40: 51 | J40: 819 | K40: 25.353766, 51.439875
...

Sheet Sheet2
A1: POINT_X | B1: POINT_Y | C1: GPs | D1: Zone Number | E1: Panel Tag at the field | F1: Relevant ITS | G1: SIRTI MENA SCOPE | H1: Survey Date | I1: KM meter Number | J1: Remarks | K1: Panrel Brand | L1: Main CB Rating | M1: Panel Condition (1 to 5) | N1: INSPECTOR | O1: Mounting Type | P1: Mounting Height (CM) | Q1: Contactor Capacity | R1: MCCB Manufacturer | S1: Model Number | T1: ASSET_TAG | U1: MXASSETNUM
A2: 51.444057 | B2: 25.155561 | C2: =A2&" "&B2 -> 51.444057 25.155561 | D2: 57 | E2: ITS- IFP-18 | F2: ENC-30/31 | G2: Y | H2: 46102 | I2: 1391195 | J2: ENC-30/31 conneceted to ITS-FP-18 | K2: schenider | M2: 3 | N2: Eric | O2: Floor Mounting | P2: 160 | Q2: 100A | R2: SIEMENS | S2: NSYPL1073G | T2: DA57-EXP2000-ITS-IFP-03202 | U2: 15717762
A3: 51.446099 | B3: 25.15252 | C3: =A3&" "&B3 -> 51.446099 25.15252 | D3: 91 | E3: ITS-FP-21 | F3: ENC-28,29 &31 | G3: Y | H3: 46072 | I3: 1376728 | J3: N/A | K3: Schneider Electric single door | L3: 100A | M3: 3 | N3: Eric | O3: Floor Mounting | P3: 160 | Q3: 100A | R3: SIEMENS | S3: NSYPL1073G | T3: WA91-SEC2020-ITS-IFP-03101 | U3: 15717763
A4: 51.471713 | B4: 25.16626 | C4: =A4&" "&B4 -> 51.471713 25.16626 | D4: 57 | E4: ITS- IFP-05602 | F4: ENC-57 | G4: Y | H4: 46102 | I4: N/A | J4: ENC-57 conneceted to ITS-FP | K4: schenider | M4: 3 | N4: Eric | O4: Floor Mounting | P4: 160 | Q4: 100A | R4: SIEMENS | S4: NSYPL1073G | T4: DA57-EXP2000-ITS-IFP-05602 | U4: 15717779
A5: 51.473238 | B5: 25.162045 | C5: =A5&" "&B5 -> 51.473238 25.162045 | D5: 91 | E5: ITS-FP-37 | F5: ENC-53,54 &51A | G5: Y | H5: 46084 | I5: 1376615 | J5: ATS on site | K5: Schneider Electric single door | L5: 100A | M5: 3 | N5: Eric | O5: Floor Mounting | P5: 160 | Q5: 100A | R5: SIEMENS | S5: NSYPL1073G | T5: WA91-EXP0490-ITS-IFP-05401 | U5: 15717780
A6: 51.492865 | B6: 25.172 | C6: =A6&" "&B6 -> 51.492865 25.172 | D6: 91 | E6: ITS-FP-51 | F6: ENC-80 | G6: Y | H6: 46077 | I6: 1376715 | J6: ATS on site | K6: Schneider Electric single door | L6: 100A | M6: 3 | N6: Eric | O6: Floor Mounting | P6: 160 | Q6: 100A | R6: SIEMENS | S6: NSYPL1073G | T6: WA91-SEC2028-ITS-IFP-08001 | U6: 15717782
A7: 51.490491 | B7: 25.174092 | C7: =A7&" "&B7 -> 51.490491 25.174092 | D7: 56 | E7: ITS-FP-53 | F7: ITS-FP-53 | G7: Y | H7: 46091 | I7: 1390958 | J7: ATS on site | K7: Schneider Electric single door | L7: 100A | M7: 2 | N7: Farooq | O7: Floor Mounting | P7: 160 | Q7: 100A | R7: SIEMENS | S7: NSYPL1073G | T7: RA56-EXP2000-ITS-IFP-07901 | U7: 15717783
A8: 51.430403 | B8: 25.150106 | C8: =A8&" "&B8 -> 51.430403 25.150106 | D8: 81 | E8: P0-FP-ITS-14 | F8: ENC-19 & 21 | G8: Y | H8: 46097 | I8: N/A | J8: ATS on site | K8: Schneider Electric single door | M8: 3 | N8: Patrick | O8: Floor Mounting | P8: 160 | Q8: 160A | R8: GE FD160 | S8: NSYPL1073G | T8: RA81-EXP2000-ITS-IFP-01901 | U8: 15725150
A9: 51.407408 | B9: 25.139912 | C9: =A9&" "&B9 -> 51.407408 25.139912 | D9: 1 | E9: ITS-IFP-00101 | F9: ENC-01 | G9: Y | H9: 46087 | I9: N/A | J9: ENC-01 conneceted to ITS-FP | K9: Schneider Electric single door | L9: 100A | M9: 2 | N9: Eric | O9: Floor Mounting | P9: 160 | Q9: 100A | R9: SIEMENS | S9: NSYPL1073G | T9: RA81-EXP2000-ITS-IFP-00101 | U9: 15725151
A10: 51.423713 | B10: 25.147197 | C10: =A10&" "&B10 -> 51.423713 25.147197 | D10: 81 | E10: ITS-FP-12 | F10: ENC-16&17 | G10: Y | H10: 46084 | I10: 1376735 | J10: ENC-16 ENC-17 conneceted to ITS-FP12, Have ATS | K10: Schneider Electric single door | L10: 100A | M10: 3 | N10: Eric | O10: Floor Mounting | P10: 160 | Q10: 100A | R10: SIEMENS | S10: NSYPL1073G | T10: RA81-EXP2000-ITS-IFP-01501 | U10: 15725152
A11: 51.414039 | B11: 25.142917 | C11: =A11&" "&B11 -> 51.414039 25.142917 | D11: 81 | E11: P10-FP-ITS-4 | F11: ENC-09 & 04 | G11: Y | H11: 46097 | I11: N/A | J11: ATS on site and Main MCB is connected to P0-FP-ITS-4A | K11: Schneider Electric single door | M11: 3 | N11: Patrick | O11: Floor Mounting | P11: 160 | Q11: 100A | R11: SIEMENS | S11: NSYPL1073G | T11: RA81-EXP2000-ITS-IFP-00302 | U11: 15725153
A12: 51.416448 | B12: 25.146288 | C12: =A12&" "&B12 -> 51.416448 25.146288 | D12: 81 | E12: ITS-FP-6 | F12: N/A | G12: Y | H12: 46087 | I12: 1376737 | J12: ATS on site | K12: Schneider Electric single door | L12: 100A | M12: 3 | N12: Eric | O12: Floor Mounting | P12: 160 | Q12: 100A | R12: SIEMENS | S12: NSYPL1073G | T12: RA81-EXP2000-ITS-IFP-01201 | U12: 15725154
A13: 51.416976 | B13: 25.1481 | C13: =A13&" "&B13 -> 51.416976 25.1481 | D13: 81 | E13: PO-ITS-FP-14 | F13: ENC 19 & 21 | G13: Y | H13: 46089 | I13: 1390965 | J13: N/A | K13: Schneider Electric single door | M13: 3 | N13: Eric | O13: Floor Mounting | P13: 160 | Q13: 100A | R13: SIEMENS | S13: NSYPL1073G | T13: RA81-SEC0200-ITS-IFP-01301 | U13: 15725155
A14: 51.419291 | B14: 25.144655 | C14: =A14&" "&B14 -> 51.419291 25.144655 | D14: 81 | E14: ITS-FP-01402 | F14: ENC-14 | G14: Y | H14: 46084 | I14: 1390496 | J14: N/A | K14: Schneider Electric single door | L14: 100A | M14: 3 | N14: Eric | O14: Floor Mounting | P14: 160 | Q14: 160A | R14: SIEMENS | S14: NSYPL1073G | T14: RA81-EXP2000-ITS-IFP-01402 | U14: 15725156
A15: 51.485952 | B15: 25.169957 | C15: =A15&" "&B15 -> 51.485952 25.169957 | D15: 91 | E15: ITS-FP-43 | F15: ENC 70 | G15: Y | H15: 46086 | I15: 1390961 | J15: Spare 32Amp 16nos | K15: Schneider Electric single door | L15: 100AMp | M15: 3 | N15: Farooq | O15: Floor Mounting | P15: 160 | Q15: 100A | R15: SIEMENS | S15: NSYPL1073G | T15: RA56-EXP2000-ITS-IFP4201 | U15: 15717598
A16: 51.344516 | B16: 25.324812 | C16: =A16&" "&B16 -> 51.344516 25.324812 | D16: 51 | E16: ITS-IFP-01 | F16: ENC-IEC-1/6 | G16: Y | H16: 46088 | I16: 1257811 | J16: ENC-IEC-1/6 CONNECTED TO ITS-FP01 | K16: Schinder | M16: 3 | N16: Eric | O16: Floor Mounting | P16: 160 | Q16: 80A | R16: SCHNEIDER | S16: NSYPL1073G | T16: RA53-PRM373-ITS-IFP-002 | U16: 16458013
A17: 51.346612 | B17: 25.324747 | C17: =A17&" "&B17 -> 51.346612 25.324747 | D17: 51 | E17: ITS- FP- 02 | F17: ENC22-PWA-5I | G17: Y | H17: 46103 | I17: 121138 | J17: ENC-22 /PWA-51 conneceted to ITS-FP | K17: schenider | M17: 3 | N17: Eric | O17: Floor Mounting | P17: 160 | Q17: 160A | R17: GE FD160 | S17: NSYPL1073G | T17: RA53-PRM373-ITS-IFP-003 | U17: 16458014
A18: 51.358676 | B18: 25.317458 | C18: =A18&" "&B18 -> 51.358676 25.317458 | D18: 53 | E18: ITS-FP-03 | F18: ENC-13&14 | G18: Y | H18: 46097 | I18: 1263839 | J18: N/A | K18: Schneider Electric single door | M18: 3 | N18: Yussuph | O18: Floor Mounting | P18: 160 | Q18: 100A | R18: SIEMENS | S18: NSYPL1073G | T18: RA53-PRM373-ITS-IFP-001 | U18: 16458028
A19: 51.558 | B19: 25.226469 | C19: =A19&" "&B19 -> 51.558 25.226469 | D19: 50 | E19: ITS-FP-10 | F19: N/A | G19: Y | H19: 46081 | I19: 1181333 | J19: N/A | K19: Schneider Electric single door | L19: 100A | M19: 3 | N19: Patrick | O19: Floor Mounting | P19: 160 | Q19: 100A | R19: SIEMENS | S19: NSYPL1073G | T19: DA50-EXP0270-ITS-IFP-02002 | U19: 16487688
A20: 51.562798 | B20: 25.228801 | C20: =A20&" "&B20 -> 51.562798 25.228801 | D20: 47 | E20: ITS-FP-13 | F20: ENC-25,26 &27 | G20: Y | H20: 46091 | I20: N/A | J20: N/A | K20: Schneider Electric single door | L20: 100A | M20: 3 | N20: Patrick | O20: Floor Mounting | P20: 160 | Q20: 100A | R20: SIEMENS | S20: NSYPL1073G | T20: DA47-EXP0270-ITS-IFP-02502 | U20: 16487689
A21: 51.468309 | B21: 25.165609 | C21: =A21&" "&B21 -> 51.468309 25.165609 | D21: 57 | E21: ITS-FP-32 | F21: ENC59 /ENC49A | G21: Y | H21: 46090 | I21: 1376618 | J21: ATS installed / CB 32A spare 16nos | K21: Schneider Single Door cabinet | L21: 100A/Siemens | M21: 3 | N21: Farooq | O21: Floor Mounting | P21: 160 | Q21: 100A | R21: SIEMENS | S21: NSYPL1073G | T21: DA57-EXP2000-ITS-IFP-04901 | U21: 15717614
A22: 51.470067 | B22: 25.170475 | C22: =A22&" "&B22 -> 51.470067 25.170475 | D22: 57 | E22: ITS-FP-34 | F22: ENC 60 & 25 | G22: Y | H22: 46088 | I22: N/A | J22: Sapre 32AMp 3nos,40AMp 1nos | K22: Schneider Single Door cabinet | L22: 100AMp | M22: 3 | N22: Farooq | O22: Floor Mounting | P22: 160 | Q22: 100a | R22: SIEMENS | S22: NSYPL1073G | T22: DA57-EXP0100-ITS-IFP-06002 | U22: 15717615
A23: 51.416771 | B23: 25.142396 | C23: =A23&" "&B23 -> 51.416771 25.142396 | D23: 91 | E23: ITS-FP-00601 | F23: N/A | G23: Y | H23: 46084 | I23: 1390497 | J23: ATS on site | K23: Schneider Electric single door | L23: 100A | M23: 2 | N23: Eric | O23: Floor Mounting | P23: 160 | Q23: 100A | R23: SIEMENS | S23: NSYPL1073G | T23: WA91-EXP2000-ITS-IFP-00601 | U23: 15717616
A24: 51.492833 | B24: 25.170045 | C24: =A24&" "&B24 -> 51.492833 25.170045 | D24: 91 | E24: ITS-FP-50 | F24: N/A | G24: Y | H24: 46077 | I24: 1376716 | J24: ATS on site | K24: Schneider Electric single door | L24: 100A | M24: 3 | N24: Eric | O24: Floor Mounting | P24: 160 | Q24: 100A | R24: SIEMENS | S24: NSYPL1073G | T24: WA91-SEC2028-ITS-IFP-08201 | U24: 15717617
A25: 51.494257 | B25: 25.174116 | C25: =A25&" "&B25 -> 51.494257 25.174116 | D25: 91 | E25: ITS-FP-52 | F25: ENC-81 | G25: Y | H25: 46098 | I25: N/A | J25: N/A | K25: Schneider Electric single door | M25: 3 | N25: Patrick | O25: Floor Mounting | P25: 160 | Q25: 100A | R25: SIEMENS | S25: NSYPL1073G | T25: WA91-EXP2000-ITS-IFP-08102 | U25: 15717618
A26: 51.427274 | B26: 25.146783 | C26: =A26&" "&B26 -> 51.427274 25.146783 | D26: 91 | E26: ITS-IFP-01701 | F26: N/A | G26: Y | H26: 46072 | I26: N/A | J26: ATS on site | K26: Schneider Electric single door | L26: 100A | M26: 3 | N26: Eric | O26: Floor Mounting | P26: 160 | Q26: 100A | R26: SIEMENS | S26: NSYPL1073G | T26: WA91-EXP2000-ITS-IFP-01701 | U26: 15717620
A27: 51.441019 | B27: 25.152775 | C27: =A27&" "&B27 -> 51.441019 25.152775 | D27: 91 | E27: ITS-FP-16 | F27: ENC-24 &24A | G27: Y | H27: 46084 | I27: N/A | J27: ATS on site | K27: Schneider | L27: 100A | M27: 3 | N27: Eric | O27: Floor Mounting | P27: 160 | Q27: 160A | R27: GE FD160 | S27: NSYPL1073G | T27: WA91-EXP2000-ITS-IFP-02601 | U27: 15717621
A28: 51.566582 | B28: 25.229503 | C28: =A28&" "&B28 -> 51.566582 25.229503 | D28: 50 | E28: ITS-FP-15 | F28: ENC-28 | G28: Y | H28: 46084 | I28: N/A | J28: N/A | K28: Schneider Electric single door | L28: 100A | M28: 3 | N28: Patrick | O28: Floor Mounting | P28: 160 | Q28: 160A | R28: GE FD160 | S28: NSYPL1073G | T28: DA50-EXP0270-ITS-IFP-02801 | U28: 16487690
A29: 51.570303 | B29: 25.230222 | C29: =A29&" "&B29 -> 51.570303 25.230222 | D29: 50 | E29: ITS-FP-16 | F29: N/A | G29: Y | H29: 46075 | I29: 1392801 | J29: N/A | K29: Shneider Electric single door | L29: 230A | M29: 3 | N29: Patrick | O29: Floor Mounting | P29: 160 | Q29: 100A | R29: SIEMENS | S29: NSYPL1073G | T29: DA50-EXP0270-ITS-IFP-02901 | U29: 16487691
A30: 51.386284 | B30: 25.312505 | C30: =A30&" "&B30 -> 51.386284 25.312505 | D30: 51 | E30: ITS-IFP-0002 | F30: ENC-1 ENC-2 | G30: Y | H30: 46088 | I30: N/A | J30: ENC-1 ENC- conneceted to ITS-FP0002 | K30: Schinder | M30: 3 | N30: Eric | O30: Floor Mounting | P30: 160 | Q30: 100A | R30: SIEMENS | S30: NSYPL1073G | T30: RA51-EXP0373-ITS-IFP-00102 | U30: 16487692
A31: 51.38368 | B31: 25.311931 | C31: =A31&" "&B31 -> 51.38368 25.311931 | D31: 53 | E31: N/A | F31: N/A | G31: N | H31: 46097 | I31: N/A | J31: N/A | K31: N/A | M31: N/A | N31: KHADAR | O31: N/A | P31: N/A | Q31: N/A | R31: N/A | S31: N/A | T31: RA53-PRM0373-ITS-IFP-0001 | U31: 16487693
A32: 51.379019 | B32: 25.31271 | C32: =A32&" "&B32 -> 51.379019 25.31271 | D32: 53 | E32: ITS- FP- 03 | F32: ENC -03/04/05 | G32: Y | H32: 46103 | I32: 1392799 | J32: ENC-03/04/04 conneceted to ITS-FP03 | K32: schenider | M32: 3 | N32: Eric | O32: Floor Mounting | P32: 160 | Q32: 100A | R32: SIEMENS | S32: NSYPL1073G | T32: RA53-EXP0373-ITS-IFP-00301 | U32: 16487694
A33: 51.366198 | B33: 25.315193 | C33: =A33&" "&B33 -> 51.366198 25.315193 | D33: 53 | E33: ITS-FP-04 | F33: ENC-6, 7&8 | G33: Y | H33: 46097 | I33: N/A | J33: N/A | K33: Schneider Electric single door | M33: 3 | N33: Yussuph | O33: Floor Mounting | P33: 160 | Q33: 160A | R33: GE FD160 | S33: NSYPL1073G | T33: RA53-EXP0373-ITS-IFP-00901 | U33: 16487695
A34: 51.371097 | B34: 25.314265 | C34: =A34&" "&B34 -> 51.371097 25.314265 | D34: 53 | E34: ITS- IFP-0004 | F34: ENC -06/08/09 | G34: Y | H34: 46103 | I34: 1170658 | J34: ENC--06/08/09 conneceted to ITS-FP0004 | K34: schenider | M34: 3 | N34: Eric | O34: Floor Mounting | P34: 160 | Q34: 100A | R34: SIEMENS | S34: NSYPL1073G | T34: RA53-EXP0373-ITS-IFP-00601 | U34: 16487696
A35: 51.362707 | B35: 25.317222 | C35: =A35&" "&B35 -> 51.362707 25.317222 | D35: 51 | E35: P04/ITS-FP-06 | F35: ENC 11 & 12 | G35: Y | H35: 46095 | I35: N/A | J35: Kaharama installed but still no power meter | K35: Schneider Electric single door | L35: 100 Amp | M35: 4 | N35: Farooq | O35: Floor Mounting | P35: 160 | Q35: 160A | R35: GE FD160 | S35: NSYPL1073G | T35: RA51-EXP0373-ITS-IFP-01101 | U35: 16487697
A36: 51.358933 | B36: 25.317274 | C36: =A36&" "&B36 -> 51.358933 25.317274 | D36: 53 | E36: N/A | F36: N/A | G36: N | H36: 46097 | I36: N/A | J36: N/A | K36: N/A | M36: N/A | N36: Yussuph | O36: N/A | P36: N/A | Q36: N/A | R36: N/A | S36: N/A | T36: RA53-PRM0373-ITS-IFP-0004 | U36: 16487698
A37: 51.361317 | B37: 25.316498 | C37: =A37&" "&B37 -> 51.361317 25.316498 | D37: 53 | E37: ITS-FP-05 | F37: ENC09&10 | G37: Y | H37: 46097 | I37: N/A | J37: N/A | K37: Schneider Electric single door | M37: 3 | N37: Yussuph | O37: Floor Mounting | P37: 160 | Q37: 160A | R37: GE FD160 | S37: NSYPL1073G | T37: RA53-PRM0373-ITS-IFP-0005 | U37: 16487699
A38: 51.355372 | B38: 25.320754 | C38: =A38&" "&B38 -> 51.355372 25.320754 | D38: 51 | E38: ITS-FP-03 | F38: N/A | G38: Y | H38: 46088 | I38: N//A | J38: NO WORKING ITS-FP-O3 | K38: Schinder | M38: 3 | N38: Eric | O38: Floor Mounting | P38: 160 | Q38: 100A | R38: SIEMENS | S38: NSYPL1073G | T38: RA51-PRM0373-ITS-IFP-0003 | U38: 16487700
A39: 51.45364 | B39: 25.157946 | C39: =A39&" "&B39 -> 51.45364 25.157946 | D39: 91 | E39: ITS-FP-24 | F39: ENC-39 | G39: Y | H39: 46085 | I39: 1390541 | J39: ATS on site | K39: Schneider Electric single door | L39: 100A | M39: 3 | N39: Eric | O39: Floor Mounting | P39: 160 | Q39: 100A | R39: SIEMENS | S39: NSYPL1073G | T39: WA91-EXP2000-ITS-IFP-03901 | U39: 15717639
A40: 51.352045 | B40: 25.317916 | C40: =A40&" "&B40 -> 51.352045 25.317916 | D40: 53 | E40: P04-ITS-FP-09 | F40: ENC-17 ENC-18 ENC-19 | G40: Y | H40: 46097 | I40: N/A | J40: NO KM NUMBER | K40: Schneider Electric single door | M40: 3 | N40: KHADAR | O40: Floor Mounting | P40: 160 | Q40: 100A | R40: SIEMENS | S40: NSYPL1073G | T40: RA53-EXP0621-ITS-IFP-01701 | U40: 16487701
...
